Workbook
Name \c: [1]NOV96!#REF!
Name \c: [1]NOV96!#REF!
Name \l: '[2]97WALK'!#REF!
Name \l: '[2]97WALK'!#REF!
Name \m: '[2]97WALK'!#REF!
Name \m: '[2]97WALK'!#REF!
Name \p: '[2]97WALK'!#REF!
Name \p: '[2]97WALK'!#REF!
Name __2_Avail_by_Option_ID_w_Vendor__AllDates_NO_Countries: #REF!
Name __2_Avail_by_Option_ID_w_Vendor__AllDates_NO_Countries: #REF!
Name __coa4: [8]Mapping!#REF!
Name __coa4: [8]Mapping!#REF!
Name __DAT1: #REF!
Name __DAT1: #REF!
Name __DAT10: #REF!
Name __DAT10: #REF!
Name __DAT11: #REF!
Name __DAT11: #REF!
Name __DAT12: #REF!
Name __DAT12: #REF!
Name __DAT13: #REF!
Name __DAT13: #REF!
Name __DAT14: #REF!
Name __DAT14: #REF!
Name __DAT15: #REF!
Name __DAT15: #REF!
Name __DAT16: #REF!
Name __DAT16: #REF!
Name __DAT17: #REF!
Name __DAT17: #REF!
Name __DAT18: #REF!
Name __DAT18: #REF!
Name __DAT19: #REF!
Name __DAT19: #REF!
Name __DAT2: #REF!
Name __DAT2: #REF!
Name __DAT20: #REF!
Name __DAT20: #REF!
Name __DAT21: #REF!
Name __DAT21: #REF!
Name __DAT22: #REF!
Name __DAT22: #REF!
Name __DAT23: #REF!
Name __DAT23: #REF!
Name __DAT24: #REF!
Name __DAT24: #REF!
Name __DAT25: #REF!
Name __DAT25: #REF!
Name __DAT26: #REF!
Name __DAT26: #REF!
Name __DAT27: #REF!
Name __DAT27: #REF!
Name __DAT28: #REF!
Name __DAT28: #REF!
Name __DAT29: #REF!
Name __DAT29: #REF!
Name __DAT3: #REF!
Name __DAT3: #REF!
Name __DAT30: #REF!
Name __DAT30: #REF!

Sheet APROVEITAMENTO
A1: PREVENTIVA DE NOVEMBRO 2017
D2: BTS/TX | I2: ESTRUTURAL TORRE | N2: GMG | S2: INFRA | X2: EVT | AC2: RAMAL DE AC | AH2: REPETIDOR | AM2: SITES ULTIMA MILHA | AR2: CCC´S | AW2: FMT | BB2: TOTAL
A3: DDD | B3: ÁREA | C3: SUPERVISOR | D3: PR | E3: EX | F3: REL | G3: APROV | H3: REAL | I3: PR | J3: EX | K3: REL | L3: APROV | M3: REAL | N3: PR | O3: EX | P3: REL | Q3: APROV | R3: REAL | S3: PR | T3: EX | U3: REL | V3: APROV | W3: REAL | X3: PR | Y3: EX | Z3: REL | AA3: APROV | AB3: REAL | AC3: PR | AD3: EX | AE3: REL | AF3: APROV | AG3: REAL | AH3: PR | AI3: EX | AJ3: REL | AK3: APROV | AL3: REAL | AM3: PR | AN3: EX | AO3: REL | AP3: APROV | AQ3: REAL | AR3: PR | AS3: EX | AT3: REL | AU3: APROV | AV3: REAL | AW3: PR | AX3: EX | AY3: REL | AZ3: APROV | BA3: REAL | BB3: PROGRAMADOf | BC3: EXECUTADOf | BD3: RELATORIO | BE3: % CONCLUÍDOf | BF3: REALf
A4: 12 | B4: SJC | C4: DENILSON ANDRADE DE MELO | D4: =COUNTIF('BTS-TX'!E$4:E$4199,"SJC") -> 26 | E4: =COUNTIFS('BTS-TX'!$E$4:$E$4199,"SJC",'BTS-TX'!$H$4:$H$4199,"<>") -> 26 | F4: =COUNTIFS('BTS-TX'!$E$4:$E$4199,"SJC",'BTS-TX'!$I$4:$I$4199,"<>") -> 26 | G4: =IF(D4=0,"",(E4/D4)) -> 1 | H4: =IF(D4=0,"",(F4/D4)) -> 1 | I4: =COUNTIF('Estrutural Torre'!E$4:E$4499,"SJC") -> 24 | J4: =COUNTIFS('Estrutural Torre'!E$4:E$4499,"SJC",'Estrutural Torre'!H$4:H$4499,"<>") -> 24 | K4: =COUNTIFS('Estrutural Torre'!$E$4:$E$4199,"SJC",'Estrutural Torre'!$I$4:$I$4199,"<>") -> 24 | L4: =IF(I4=0,"",(J4/I4)) -> 1 | M4: =IF(I4=0,"",(K4/I4)) -> 1 | R4: =IF(N4=0,"",(P4/N4)) | S4: =COUNTIF(Infra!E$4:E$4997,"SJC") -> 67 | T4: =COUNTIFS(Infra!E$4:E$4997,"SJC",Infra!H$4:H$4997,"<>") -> 67 | U4: =COUNTIFS(Infra!E$4:E$4997,"SJC",Infra!I$4:I$4997,"<>") -> 67 | V4: =IF(S4=0,"",(T4/S4)) -> 1 | W4: =IF(S4=0,"",(U4/S4)) -> 1 | AR4: =COUNTIF(CCCs!C$3:F$100,"SJC") -> 2 | AS4: =COUNTIFS(CCCs!F$3:F$100,"SJC",CCCs!J$3:J$100,"<>") -> 2 | AT4: =COUNTIFS(CCCs!F$3:F$100,"SJC",CCCs!K$3:K$100,"<>") -> 2 | AU4: =IF(AR4=0,"",(AS4/AR4)) -> 1 | AV4: =IF(AR4=0,"",(AT4/AR4)) -> 1 | AW4: 0 | AX4: 0 | AY4: 0 | AZ4: 0 | BA4: 0 | BB4: =D4+I4+N4+S4+X4+AC4+AH4+AM4+AR4+AW4 -> 119 | BC4: =E4+J4+O4+T4+Y4+AD4+AI4+AN4+AS4+AX4 -> 119 | BD4: =F4+K4+P4+U4+AT4 -> 119 | BE4: =BC4/BB4 -> 1 | BF4: =BD4/BB4 -> 1
A5: 13 | B5: STS | C5: MARIO ROGERIO DOS SANTOS | D5: =COUNTIF('BTS-TX'!E$4:E$4499,"STS") -> 28 | E5: =COUNTIFS('BTS-TX'!E$4:E$4499,"STS",'BTS-TX'!H$4:H$4499,"<>") -> 28 | F5: =COUNTIFS('BTS-TX'!$E$4:$E$4499,"STS",'BTS-TX'!$I$4:$I$4499,"<>") -> 26 | G5: =IF(D5=0,"",(E5/D5)) -> 1 | H5: =IF(D5=0,"",(F5/D5)) -> 0.92857143 | I5: =COUNTIF('Estrutural Torre'!E$4:E$4499,"STS") -> 26 | J5: =COUNTIFS('Estrutural Torre'!E$4:E$4499,"STS",'Estrutural Torre'!H$4:H$4499,"<>") -> 26 | K5: =COUNTIFS('Estrutural Torre'!$E$4:$E$4199,"STS",'Estrutural Torre'!$I$4:$I$4199,"<>") -> 0 | L5: =IF(I5=0,"",(J5/I5)) -> 1 | M5: =IF(I5=0,"",(K5/I5)) -> 0 | R5: =IF(N5=0,"",(P5/N5)) | S5: =COUNTIF(Infra!E$4:E$4997,"STS") -> 54 | T5: =COUNTIFS(Infra!E$4:E$4997,"STS",Infra!H$4:H$4997,"<>") -> 53 | U5: =COUNTIFS(Infra!E$4:E$4997,"STS",Infra!I$4:I$4997,"<>") -> 53 | V5: =IF(S5=0,"",(T5/S5)) -> 0.98148148 | W5: =IF(S5=0,"",(U5/S5)) -> 0.98148148 | AR5: 0 | AS5: 0 | AT5: 0 | AU5: 0 | AV5: 0 | AW5: 0 | AX5: 0 | AY5: 0 | AZ5: 0 | BA5: 0 | BB5: =D5+I5+N5+S5+X5+AC5+AH5+AM5+AR5+AW5 -> 108 | BC5: =E5+J5+O5+T5+Y5+AD5+AI5+AN5+AS5+AX5 -> 107 | BD5: =F5+K5+P5+U5+Z5+AE5+AJ5+AO5+AT5+AY5 -> 79 | BE5: =BC5/BB5 -> 0.99074074 | BF5: =BD5/BB5 -> 0.73148148
A6: 14 | B6: BRU | C6: REINALDO SOARES CAMARGO | D6: =COUNTIF('BTS-TX'!E$4:E$4499,"BRU") -> 15 | E6: =COUNTIFS('BTS-TX'!E$4:E$4499,"BRU",'BTS-TX'!H$4:H$4499,"<>") -> 15 | F6: =COUNTIFS('BTS-TX'!$E$4:$E$4499,"BRU",'BTS-TX'!$I$4:$I$4499,"<>") -> 15 | G6: =IF(D6=0,"",(E6/D6)) -> 1 | H6: =IF(D6=0,"",(F6/D6)) -> 1 | I6: =COUNTIF('Estrutural Torre'!E$4:E$4499,"BRU") -> 15 | J6: =COUNTIFS('Estrutural Torre'!E$4:E$4499,"BRU",'Estrutural Torre'!H$4:H$4499,"<>") -> 15 | K6: =COUNTIFS('Estrutural Torre'!$E$4:$E$4199,"BRU",'Estrutural Torre'!$I$4:$I$4199,"<>") -> 15 | L6: =IF(I6=0,"",(J6/I6)) -> 1 | M6: =IF(I6=0,"",(K6/I6)) -> 1 | R6: =IF(N6=0,"",(P6/N6)) | S6: =COUNTIF(Infra!E$4:E$4997,"BRU") -> 41 | T6: =COUNTIFS(Infra!E$4:E$4997,"BRU",Infra!H$4:H$4997,"<>") -> 41 | U6: =COUNTIFS(Infra!E$4:E$4997,"BRU",Infra!I$4:I$4997,"<>") -> 41 | V6: =IF(S6=0,"",(T6/S6)) -> 1 | W6: =IF(S6=0,"",(U6/S6)) -> 1 | AR6: =COUNTIF(CCCs!C$3:F$100,"BRU") -> 1 | AS6: =COUNTIFS(CCCs!F$3:F$100,"BRU",CCCs!J$3:J$100,"<>") -> 1 | AT6: =COUNTIFS(CCCs!F$3:F$100,"BRU",CCCs!K$3:K$100,"<>") -> 1 | AU6: =IF(AR6=0,"",(AS6/AR6)) -> 1 | AV6: =IF(AR6=0,"",(AT6/AR6)) -> 1 | AW6: 0 | AX6: 0 | AY6: 0 | AZ6: 0 | BA6: 0 | BB6: =D6+I6+N6+S6+X6+AC6+AH6+AM6+AR6+AW6 -> 72 | BC6: =E6+J6+O6+T6+Y6+AD6+AI6+AN6+AS6+AX6 -> 72 | BD6: =F6+K6+P6+U6+Z6+AE6+AJ6+AO6+AT6+AY6 -> 72 | BE6: =BC6/BB6 -> 1 | BF6: =BD6/BB6 -> 1
A7: 15 | B7: SOC | C7: PAULO ROBERTO DOS SANTOS | D7: =COUNTIF('BTS-TX'!E$4:E$4499,"SOC") -> 10 | E7: =COUNTIFS('BTS-TX'!E$4:E$4499,"SOC",'BTS-TX'!H$4:H$4499,"<>") -> 10 | F7: =COUNTIFS('BTS-TX'!$E$4:$E$4499,"SOC",'BTS-TX'!$I$4:$I$4499,"<>") -> 10 | G7: =IF(D7=0,"",(E7/D7)) -> 1 | H7: =IF(D7=0,"",(F7/D7)) -> 1 | I7: =COUNTIF('Estrutural Torre'!E$4:E$4499,"SOC") -> 10 | J7: =COUNTIFS('Estrutural Torre'!E$4:E$4499,"SOC",'Estrutural Torre'!H$4:H$4499,"<>") -> 10 | K7: =COUNTIFS('Estrutural Torre'!$E$4:$E$4199,"SOC",'Estrutural Torre'!$I$4:$I$4199,"<>") -> 10 | L7: =IF(I7=0,"",(J7/I7)) -> 1 | M7: =IF(I7=0,"",(K7/I7)) -> 1 | R7: =IF(N7=0,"",(P7/N7)) | S7: =COUNTIF(Infra!E$4:E$4997,"SOC") -> 35 | T7: =COUNTIFS(Infra!E$4:E$4997,"SOC",Infra!H$4:H$4997,"<>") -> 35 | U7: =COUNTIFS(Infra!E$4:E$4997,"SOC",Infra!I$4:I$4997,"<>") -> 35 | V7: =IF(S7=0,"",(T7/S7)) -> 1 | W7: =IF(S7=0,"",(U7/S7)) -> 1 | AR7: =COUNTIF(CCCs!C$3:F$100,"SOC") -> 1 | AS7: =COUNTIFS(CCCs!F$3:F$100,"SOC",CCCs!J$3:J$100,"<>") -> 1 | AT7: =COUNTIFS(CCCs!F$3:F$100,"SOC",CCCs!K$3:K$100,"<>") -> 1 | AU7: =IF(AR7=0,"",(AS7/AR7)) -> 1 | AV7: =IF(AR7=0,"",(AT7/AR7)) -> 1 | AW7: 0 | AX7: 0 | AY7: 0 | AZ7: 0 | BA7: 0 | BB7: =D7+I7+N7+S7+X7+AC7+AH7+AM7+AR7+AW7 -> 56 | BC7: =E7+J7+O7+T7+Y7+AD7+AI7+AN7+AS7+AX7 -> 56 | BD7: =F7+K7+P7+U7+Z7+AE7+AJ7+AO7+AT7+AY7 -> 56 | BE7: =BC7/BB7 -> 1 | BF7: =BD7/BB7 -> 1
A8: 16 | B8: RPO | C8: MARCOS LEANDRO MIGUELETI DE CARVALHO | D8: =COUNTIF('BTS-TX'!E$4:E$4499,"RPO") -> 19 | E8: =COUNTIFS('BTS-TX'!E$4:E$4499,"RPO",'BTS-TX'!H$4:H$4499,"<>") -> 19 | F8: =COUNTIFS('BTS-TX'!$E$4:$E$4499,"RPO",'BTS-TX'!$I$4:$I$4499,"<>") -> 19 | G8: =IF(D8=0,"",(E8/D8)) -> 1 | H8: =IF(D8=0,"",(F8/D8)) -> 1 | I8: =COUNTIF('Estrutural Torre'!E$4:E$4499,"RPO") -> 19 | J8: =COUNTIFS('Estrutural Torre'!E$4:E$4499,"RPO",'Estrutural Torre'!H$4:H$4499,"<>") -> 19 | K8: =COUNTIFS('Estrutural Torre'!$E$4:$E$4199,"RPO",'Estrutural Torre'!$I$4:$I$4199,"<>") -> 19 | L8: =IF(I8=0,"",(J8/I8)) -> 1 | M8: =IF(I8=0,"",(K8/I8)) -> 1 | R8: =IF(N8=0,"",(P8/N8)) | S8: =COUNTIF(Infra!E$4:E$4997,"RPO") -> 44 | T8: =COUNTIFS(Infra!E$4:E$4997,"RPO",Infra!H$4:H$4997,"<>") -> 44 | U8: =COUNTIFS(Infra!E$4:E$4997,"RPO",Infra!I$4:I$4997,"<>") -> 44 | V8: =IF(S8=0,"",(T8/S8)) -> 1 | W8: =IF(S8=0,"",(U8/S8)) -> 1 | AR8: =COUNTIF(CCCs!C$3:F$100,"RPO") -> 1 | AS8: =COUNTIFS(CCCs!F$3:F$100,"RPO",CCCs!J$3:J$100,"<>") -> 1 | AT8: =COUNTIFS(CCCs!F$3:F$100,"RPO",CCCs!K$3:K$100,"<>") -> 1 | AU8: =IF(AR8=0,"",(AS8/AR8)) -> 1 | AV8: =IF(AR8=0,"",(AT8/AR8)) -> 1 | AW8: 0 | AX8: 0 | AY8: 0 | AZ8: 0 | BA8: 0 | BB8: =D8+I8+N8+S8+X8+AC8+AH8+AM8+AR8+AW8 -> 83 | BC8: =E8+J8+O8+T8+Y8+AD8+AI8+AN8+AS8+AX8 -> 83 | BD8: =F8+K8+P8+U8+Z8+AE8+AJ8+AO8+AT8+AY8 -> 83 | BE8: =BC8/BB8 -> 1 | BF8: =BD8/BB8 -> 1
A9: 17 | B9: SRR | C9: MILTON SONEHARA | D9: =COUNTIF('BTS-TX'!E$4:E$4499,"SRR") -> 10 | E9: =COUNTIFS('BTS-TX'!E$4:E$4499,"SRR",'BTS-TX'!H$4:H$4499,"<>") -> 10 | F9: =COUNTIFS('BTS-TX'!$E$4:$E$4499,"SRR",'BTS-TX'!$I$4:$I$4499,"<>") -> 10 | G9: =IF(D9=0,"",(E9/D9)) -> 1 | H9: =IF(D9=0,"",(F9/D9)) -> 1 | I9: =COUNTIF('Estrutural Torre'!E$4:E$4499,"SRR") -> 10 | J9: =COUNTIFS('Estrutural Torre'!E$4:E$4499,"SRR",'Estrutural Torre'!H$4:H$4499,"<>") -> 10 | K9: =COUNTIFS('Estrutural Torre'!$E$4:$E$4199,"SRR",'Estrutural Torre'!$I$4:$I$4199,"<>") -> 10 | L9: =IF(I9=0,"",(J9/I9)) -> 1 | M9: =IF(I9=0,"",(K9/I9)) -> 1 | R9: =IF(N9=0,"",(P9/N9)) | S9: =COUNTIF(Infra!E$4:E$4997,"SRR") -> 36 | T9: =COUNTIFS(Infra!E$4:E$4997,"SRR",Infra!H$4:H$4997,"<>") -> 36 | U9: =COUNTIFS(Infra!E$4:E$4997,"SRR",Infra!I$4:I$4997,"<>") -> 36 | V9: =IF(S9=0,"",(T9/S9)) -> 1 | W9: =IF(S9=0,"",(U9/S9)) -> 1 | AR9: =COUNTIF(CCCs!C$3:F$100,"SRR") -> 1 | AS9: =COUNTIFS(CCCs!F$3:F$100,"SRR",CCCs!J$3:J$100,"<>") -> 1 | AT9: =COUNTIFS(CCCs!F$3:F$100,"SRR",CCCs!K$3:K$100,"<>") -> 1 | AU9: =IF(AR9=0,"",(AS9/AR9)) -> 1 | AV9: =IF(AR9=0,"",(AT9/AR9)) -> 1 | AW9: 0 | AX9: 0 | AY9: 0 | AZ9: 0 | BA9: 0 | BB9: =D9+I9+N9+S9+X9+AC9+AH9+AM9+AR9+AW9 -> 57 | BC9: =E9+J9+O9+T9+Y9+AD9+AI9+AN9+AS9+AX9 -> 57 | BD9: =F9+K9+P9+U9+Z9+AE9+AJ9+AO9+AT9+AY9 -> 57 | BE9: =BC9/BB9 -> 1 | BF9: =BD9/BB9 -> 1
A10: 18 | B10: PPE | C10: ROGERIO CARNELOS MARSICANO | D10: =COUNTIF('BTS-TX'!E$4:E$4499,"PPE") -> 13 | E10: =COUNTIFS('BTS-TX'!E$4:E$4499,"PPE",'BTS-TX'!H$4:H$4499,"<>") -> 13 | F10: =COUNTIFS('BTS-TX'!$E$4:$E$4499,"PPE",'BTS-TX'!$I$4:$I$4499,"<>") -> 13 | G10: =IF(D10=0,"",(E10/D10)) -> 1 | H10: =IF(D10=0,"",(F10/D10)) -> 1 | I10: =COUNTIF('Estrutural Torre'!E$4:E$4499,"PPE") -> 13 | J10: =COUNTIFS('Estrutural Torre'!E$4:E$4499,"PPE",'Estrutural Torre'!H$4:H$4499,"<>") -> 13 | K10: =COUNTIFS('Estrutural Torre'!$E$4:$E$4199,"PPE",'Estrutural Torre'!$I$4:$I$4199,"<>") -> 13 | L10: =IF(I10=0,"",(J10/I10)) -> 1 | M10: =IF(I10=0,"",(K10/I10)) -> 1 | R10: =IF(N10=0,"",(P10/N10)) | S10: =COUNTIF(Infra!E$4:E$4997,"PPE") -> 23 | T10: =COUNTIFS(Infra!E$4:E$4997,"PPE",Infra!H$4:H$4997,"<>") -> 23 | U10: =COUNTIFS(Infra!E$4:E$4997,"PPE",Infra!I$4:I$4997,"<>") -> 23 | V10: =IF(S10=0,"",(T10/S10)) -> 1 | W10: =IF(S10=0,"",(U10/S10)) -> 1 | AR10: =COUNTIF(CCCs!C$3:F$100,"PPE") -> 1 | AS10: =COUNTIFS(CCCs!F$3:F$100,"PPE",CCCs!J$3:J$100,"<>") -> 1 | AT10: =COUNTIFS(CCCs!F$3:F$100,"PPE",CCCs!K$3:K$100,"<>") -> 1 | AU10: =IF(AR10=0,"",(AS10/AR10)) -> 1 | AV10: =IF(AR10=0,"",(AT10/AR10)) -> 1 | AW10: 0 | AX10: 0 | AY10: 0 | AZ10: 0 | BA10: 0 | BB10: =D10+I10+N10+S10+X10+AC10+AH10+AM10+AR10+AW10 -> 50 | BC10: =E10+J10+O10+T10+Y10+AD10+AI10+AN10+AS10+AX10 -> 50 | BD10: =F10+K10+P10+U10+Z10+AE10+AJ10+AO10+AT10+AY10 -> 50 | BE10: =BC10/BB10 -> 1 | BF10: =BD10/BB10 -> 1
A11: 19 | B11: CAS | C11: WESLEY OSEIAS ALVES (CAS) | D11: =COUNTIF('BTS-TX'!E$4:E$4499,"CAS") -> 25 | E11: =COUNTIFS('BTS-TX'!E$4:E$4499,"CAS",'BTS-TX'!H$4:H$4499,"<>") -> 25 | F11: =COUNTIFS('BTS-TX'!$E$4:$E$4499,"CAS",'BTS-TX'!$I$4:$I$4499,"<>") -> 13 | G11: =IF(D11=0,"",(E11/D11)) -> 1 | H11: =IF(D11=0,"",(F11/D11)) -> 0.52 | I11: =COUNTIF('Estrutural Torre'!E$4:E$4499,"CAS") -> 24 | J11: =COUNTIFS('Estrutural Torre'!E$4:E$4499,"CAS",'Estrutural Torre'!H$4:H$4499,"<>") -> 24 | K11: =COUNTIFS('Estrutural Torre'!$E$4:$E$4199,"CAS",'Estrutural Torre'!$I$4:$I$4199,"<>") -> 4 | L11: =IF(I11=0,"",(J11/I11)) -> 1 | M11: =IF(I11=0,"",(K11/I11)) -> 0.16666667 | R11: =IF(N11=0,"",(P11/N11)) | S11: =COUNTIF(Infra!E$4:E$4997,"CAS") -> 60 | T11: =COUNTIFS(Infra!E$4:E$4997,"CAS",Infra!H$4:H$4997,"<>") -> 59 | U11: =COUNTIFS(Infra!E$4:E$4997,"CAS",Infra!I$4:I$4997,"<>") -> 58 | V11: =IF(S11=0,"",(T11/S11)) -> 0.98333333 | W11: =IF(S11=0,"",(U11/S11)) -> 0.96666667 | AR11: =COUNTIF(CCCs!C$3:F$100,"CAS") -> 2 | AS11: =COUNTIFS(CCCs!F$3:F$100,"CAS",CCCs!J$3:J$100,"<>") -> 2 | AT11: =COUNTIFS(CCCs!F$3:F$100,"CAS",CCCs!K$3:K$100,"<>") -> 2 | AU11: =IF(AR11=0,"",(AS11/AR11)) -> 1 | AV11: =IF(AR11=0,"",(AT11/AR11)) -> 1 | AW11: 0 | AX11: 0 | AY11: 0 | AZ11: 0 | BA11: 0 | BB11: =D11+I11+N11+S11+X11+AC11+AH11+AM11+AR11+AW11 -> 111 | BC11: =E11+J11+O11+T11+Y11+AD11+AI11+AN11+AS11+AX11 -> 110 | BD11: =F11+K11+P11+U11+Z11+AE11+AJ11+AO11+AT11+AY11 -> 77 | BE11: =BC11/BB11 -> 0.99099099 | BF11: =BD11/BB11 -> 0.69369369
A12: 19 | B12: PAA | C12: WESLEY OSEIAS ALVES (PAA) | D12: =COUNTIF('BTS-TX'!E$4:E$4499,"PAA") -> 14 | E12: =COUNTIFS('BTS-TX'!E$4:E$4499,"PAA",'BTS-TX'!H$4:H$4499,"<>") -> 14 | F12: =COUNTIFS('BTS-TX'!$E$4:$E$4499,"PAA",'BTS-TX'!$I$4:$I$4499,"<>") -> 5 | G12: =IF(D12=0,"",(E12/D12)) -> 1 | H12: =IF(D12=0,"",(F12/D12)) -> 0.35714286 | I12: =COUNTIF('Estrutural Torre'!E$4:E$4499,"PAA") -> 15 | J12: =COUNTIFS('Estrutural Torre'!E$4:E$4499,"PAA",'Estrutural Torre'!H$4:H$4499,"<>") -> 15 | K12: =COUNTIFS('Estrutural Torre'!$E$4:$E$4199,"PAA",'Estrutural Torre'!$I$4:$I$4199,"<>") -> 0 | L12: =IF(I12=0,"",(J12/I12)) -> 1 | M12: =IF(I12=0,"",(K12/I12)) -> 0 | S12: =COUNTIF(Infra!E$4:E$4997,"PAA") -> 53 | T12: =COUNTIFS(Infra!E$4:E$4997,"PAA",Infra!H$4:H$4997,"<>") -> 53 | U12: =COUNTIFS(Infra!E$4:E$4997,"PAA",Infra!I$4:I$4997,"<>") -> 52 | V12: =IF(S12=0,"",(T12/S12)) -> 1 | W12: =IF(S12=0,"",(U12/S12)) -> 0.98113208 | AR12: 0 | AS12: 0 | AT12: 0 | AU12: 0 | AV12: 0 | AW12: 0 | AX12: 0 | AY12: 0 | AZ12: 0 | BA12: 0 | BB12: =D12+I12+N12+S12+X12+AC12+AH12+AM12+AR12+AW12 -> 82 | BC12: =E12+J12+O12+T12+Y12+AD12+AI12+AN12+AS12+AX12 -> 82 | BD12: =F12+K12+P12+U12+Z12+AE12+AJ12+AO12+AT12+AY12 -> 57 | BE12: =BC12/BB12 -> 1 | BF12: =BD12/BB12 -> 0.69512195
A13: 11 | B13: Q1 | C13: SERGIO NILTON DA CUNHA | D13: =COUNTIF('BTS-TX'!E$4:E$4499,"Q1") -> 35 | E13: =COUNTIFS('BTS-TX'!E$4:E$4499,"Q1",'BTS-TX'!H$4:H$4499,"<>") -> 35 | F13: =COUNTIFS('BTS-TX'!$E$4:$E$4499,"Q1",'BTS-TX'!$I$4:$I$4499,"<>") -> 35 | G13: =IF(D13=0,"",(E13/D13)) -> 1 | H13: =IF(D13=0,"",(F13/D13)) -> 1 | I13: =COUNTIF('Estrutural Torre'!E$4:E$4499,"Q1") -> 30 | J13: =COUNTIFS('Estrutural Torre'!E$4:E$4499,"Q1",'Estrutural Torre'!H$4:H$4499,"<>") -> 30 | K13: =COUNTIFS('Estrutural Torre'!$E$4:$E$4199,"Q1",'Estrutural Torre'!$I$4:$I$4199,"<>") -> 30 | L13: =IF(I13=0,"",(J13/I13)) -> 1 | M13: =IF(I13=0,"",(K13/I13)) -> 1 | R13: =IF(N13=0,"",(P13/N13)) | S13: =COUNTIF(Infra!E$4:E$4997,"Q1") -> 88 | T13: =COUNTIFS(Infra!E$4:E$4997,"Q1",Infra!H$4:H$4997,"<>") -> 88 | U13: =COUNTIFS(Infra!E$4:E$4997,"Q1",Infra!I$4:I$4997,"<>") -> 88 | V13: =IF(S13=0,"",(T13/S13)) -> 1 | W13: =IF(S13=0,"",(U13/S13)) -> 1 | AR13: 0 | AS13: 0 | AT13: 0 | AU13: 0 | AV13: 0 | AW13: 0 | AX13: 0 | AY13: 0 | AZ13: 0 | BA13: 0 | BB13: =D13+I13+N13+S13+X13+AC13+AH13+AM13+AR13+AW13 -> 153 | BC13: =E13+J13+O13+T13+Y13+AD13+AI13+AN13+AS13+AX13 -> 153 | BD13: =F13+K13+P13+U13+Z13+AE13+AJ13+AO13+AT13+AY13 -> 153 | BE13: =BC13/BB13 -> 1 | BF13: =BD13/BB13 -> 1
A14: 11 | B14: Q2 | C14: RODOLFO ALVES VITORINO | D14: =COUNTIF('BTS-TX'!E$4:E$4499,"Q2") -> 28 | E14: =COUNTIFS('BTS-TX'!E$4:E$4499,"Q2",'BTS-TX'!H$4:H$4499,"<>") -> 28 | F14: =COUNTIFS('BTS-TX'!$E$4:$E$4499,"Q2",'BTS-TX'!$I$4:$I$4499,"<>") -> 28 | G14: =IF(D14=0,"",(E14/D14)) -> 1 | H14: =IF(D14=0,"",(F14/D14)) -> 1 | I14: =COUNTIF('Estrutural Torre'!E$4:E$4499,"Q2") -> 20 | J14: =COUNTIFS('Estrutural Torre'!E$4:E$4499,"Q2",'Estrutural Torre'!H$4:H$4499,"<>") -> 20 | K14: =COUNTIFS('Estrutural Torre'!$E$4:$E$4199,"Q2",'Estrutural Torre'!$I$4:$I$4199,"<>") -> 20 | L14: =IF(I14=0,"",(J14/I14)) -> 1 | M14: =IF(I14=0,"",(K14/I14)) -> 1 | R14: =IF(N14=0,"",(P14/N14)) | S14: =COUNTIF(Infra!E$4:E$4997,"Q2") -> 89 | T14: =COUNTIFS(Infra!E$4:E$4997,"Q2",Infra!H$4:H$4997,"<>") -> 89 | U14: =COUNTIFS(Infra!E$4:E$4997,"Q2",Infra!I$4:I$4997,"<>") -> 89 | V14: =IF(S14=0,"",(T14/S14)) -> 1 | W14: =IF(S14=0,"",(U14/S14)) -> 1 | AR14: 0 | AS14: 0 | AT14: 0 | AU14: 0 | AV14: 0 | AW14: 0 | AX14: 0 | AY14: 0 | AZ14: 0 | BA14: 0 | BB14: =D14+I14+N14+S14+X14+AC14+AH14+AM14+AR14+AW14 -> 137 | BC14: =E14+J14+O14+T14+Y14+AD14+AI14+AN14+AS14+AX14 -> 137 | BD14: =F14+K14+P14+U14+Z14+AE14+AJ14+AO14+AT14+AY14 -> 137 | BE14: =BC14/BB14 -> 1 | BF14: =BD14/BB14 -> 1
A15: 11 | B15: Q3 | C15: RODOLFO LEITE LIMA | D15: =COUNTIF('BTS-TX'!E$4:E$4499,"Q3") -> 50 | E15: =COUNTIFS('BTS-TX'!E$4:E$4499,"Q3",'BTS-TX'!H$4:H$4499,"<>") -> 50 | F15: =COUNTIFS('BTS-TX'!$E$4:$E$4499,"Q3",'BTS-TX'!$I$4:$I$4499,"<>") -> 50 | G15: =IF(D15=0,"",(E15/D15)) -> 1 | H15: =IF(D15=0,"",(F15/D15)) -> 1 | I15: =COUNTIF('Estrutural Torre'!E$4:E$4499,"Q3") -> 36 | J15: =COUNTIFS('Estrutural Torre'!E$4:E$4499,"Q3",'Estrutural Torre'!H$4:H$4499,"<>") -> 36 | K15: =COUNTIFS('Estrutural Torre'!$E$4:$E$4199,"Q3",'Estrutural Torre'!$I$4:$I$4199,"<>") -> 36 | L15: =IF(I15=0,"",(J15/I15)) -> 1 | M15: =IF(I15=0,"",(K15/I15)) -> 1 | R15: =IF(N15=0,"",(P15/N15)) | S15: =COUNTIF(Infra!E$4:E$4997,"Q3") -> 98 | T15: =COUNTIFS(Infra!E$4:E$4997,"Q3",Infra!H$4:H$4997,"<>") -> 98 | U15: =COUNTIFS(Infra!E$4:E$4997,"Q3",Infra!I$4:I$4997,"<>") -> 98 | V15: =IF(S15=0,"",(T15/S15)) -> 1 | W15: =IF(S15=0,"",(U15/S15)) -> 1 | AR15: 0 | AS15: 0 | AT15: 0 | AU15: 0 | AV15: 0 | AW15: 0 | AX15: 0 | AY15: 0 | AZ15: 0 | BA15: 0 | BB15: =D15+I15+N15+S15+X15+AC15+AH15+AM15+AR15+AW15 -> 184 | BC15: =E15+J15+O15+T15+Y15+AD15+AI15+AN15+AS15+AX15 -> 184 | BD15: =F15+K15+P15+U15+Z15+AE15+AJ15+AO15+AT15+AY15 -> 184 | BE15: =BC15/BB15 -> 1 | BF15: =BD15/BB15 -> 1
A16: 11 | B16: Q4 | C16: WALLACE OLIVEIRA LEITE LIMA | D16: =COUNTIF('BTS-TX'!E$4:E$4499,"Q4") -> 37 | E16: =COUNTIFS('BTS-TX'!E$4:E$4499,"Q4",'BTS-TX'!H$4:H$4499,"<>") -> 37 | F16: =COUNTIFS('BTS-TX'!$E$4:$E$4499,"Q4",'BTS-TX'!$I$4:$I$4499,"<>") -> 37 | G16: =IF(D16=0,"",(E16/D16)) -> 1 | H16: =IF(D16=0,"",(F16/D16)) -> 1 | I16: =COUNTIF('Estrutural Torre'!E$4:E$4499,"Q4") -> 31 | J16: =COUNTIFS('Estrutural Torre'!E$4:E$4499,"Q4",'Estrutural Torre'!H$4:H$4499,"<>") -> 31 | K16: =COUNTIFS('Estrutural Torre'!$E$4:$E$4199,"Q4",'Estrutural Torre'!$I$4:$I$4199,"<>") -> 31 | L16: =IF(I16=0,"",(J16/I16)) -> 1 | M16: =IF(I16=0,"",(K16/I16)) -> 1 | R16: =IF(N16=0,"",(P16/N16)) | S16: =COUNTIF(Infra!E$4:E$4997,"Q4") -> 97 | T16: =COUNTIFS(Infra!E$4:E$4997,"Q4",Infra!H$4:H$4997,"<>") -> 97 | U16: =COUNTIFS(Infra!E$4:E$4997,"Q4",Infra!I$4:I$4997,"<>") -> 97 | V16: =IF(S16=0,"",(T16/S16)) -> 1 | W16: =IF(S16=0,"",(U16/S16)) -> 1 | AR16: 0 | AS16: 0 | AT16: 0 | AU16: 0 | AV16: 0 | AW16: 0 | AX16: 0 | AY16: 0 | AZ16: 0 | BA16: 0 | BB16: =D16+I16+N16+S16+X16+AC16+AH16+AM16+AR16+AW16 -> 165 | BC16: =E16+J16+O16+T16+Y16+AD16+AI16+AN16+AS16+AX16 -> 165 | BD16: =F16+K16+P16+U16+Z16+AE16+AJ16+AO16+AT16+AY16 -> 165 | BE16: =BC16/BB16 -> 1 | BF16: =BD16/BB16 -> 1
A17: 11 | B17: JAI | C17: CRISTIAN FERREIRA ROSA | D17: =COUNTIF('BTS-TX'!E$4:E$4499,"JAI") -> 11 | E17: =COUNTIFS('BTS-TX'!E$4:E$4499,"JAI",'BTS-TX'!H$4:H$4499,"<>") -> 11 | F17: =COUNTIFS('BTS-TX'!$E$4:$E$4499,"JAI",'BTS-TX'!$I$4:$I$4499,"<>") -> 5 | G17: =IF(D17=0,"",(E17/D17)) -> 1 | H17: =IF(D17=0,"",(F17/D17)) -> 0.45454545 | I17: =COUNTIF('Estrutural Torre'!E$4:E$4499,"JAI") -> 9 | J17: =COUNTIFS('Estrutural Torre'!E$4:E$4499,"JAI",'Estrutural Torre'!H$4:H$4499,"<>") -> 9 | K17: =COUNTIFS('Estrutural Torre'!$E$4:$E$4199,"JAI",'Estrutural Torre'!$I$4:$I$4199,"<>") -> 9 | L17: =IF(I17=0,"",(J17/I17)) -> 1 | M17: =IF(I17=0,"",(K17/I17)) -> 1 | R17: =IF(N17=0,"",(P17/N17)) | S17: =COUNTIF(Infra!E$4:E$4997,"JAI") -> 25 | T17: =COUNTIFS(Infra!E$4:E$4997,"JAI",Infra!H$4:H$4997,"<>") -> 25 | U17: =COUNTIFS(Infra!E$4:E$4997,"JAI",Infra!I$4:I$4997,"<>") -> 14 | V17: =IF(S17=0,"",(T17/S17)) -> 1 | W17: =IF(S17=0,"",(U17/S17)) -> 0.56 | AR17: 0 | AS17: 0 | AT17: 0 | AU17: 0 | AV17: 0 | AW17: 0 | AX17: 0 | AY17: 0 | AZ17: 0 | BA17: 0 | BB17: =D17+I17+N17+S17+X17+AC17+AH17+AM17+AR17+AW17 -> 45 | BC17: =E17+J17+O17+T17+Y17+AD17+AI17+AN17+AS17+AX17 -> 45 | BD17: =F17+K17+P17+U17+Z17+AE17+AJ17+AO17+AT17+AY17 -> 28 | BE17: =BC17/BB17 -> 1 | BF17: =BD17/BB17 -> 0.62222222
A18: 11 | B18: SPC EV | C18: LEONARDO RUGGIERO | D18: 0 | E18: 0 | F18: 0 | G18: 0 | H18: 0 | I18: =COUNTIF('Estrutural Torre'!E$4:E$4499,"SPC EV") -> 27 | J18: =COUNTIFS('Estrutural Torre'!E$4:E$4499,"SPC EV",'Estrutural Torre'!H$4:H$4499,"<>") -> 27 | K18: =COUNTIFS('Estrutural Torre'!$E$4:$E$4199,"SPC EV",'Estrutural Torre'!$I$4:$I$4199,"<>") -> 27 | L18: =IF(I18=0,"",(J18/I18)) -> 1 | M18: =IF(I18=0,"",(K18/I18)) -> 1 | S18: 0 | T18: 0 | U18: 0 | V18: 0 | W18: 0 | AR18: 0 | AS18: 0 | AT18: 0 | AU18: 0 | AV18: 0 | AW18: 0 | AX18: 0 | AY18: 0 | AZ18: 0 | BA18: 0 | BB18: =D18+I18+N18+S18+X18+AC18+AH18+AM18+AR18+AW18 -> 27 | BC18: =E18+J18+O18+T18+Y18+AD18+AI18+AN18+AS18+AX18 -> 27 | BD18: =K18 -> 27 | BE18: =BC18/BB18 -> 1 | BF18: =BD18/BB18 -> 1
A19: 11 | B19: SPC FMT | C19: ADSTON BARBOSA DOS SANTOS | D19: 0 | E19: 0 | F19: 0 | G19: 0 | H19: 0 | I19: 0 | J19: 0 | K19: =COUNTIFS('Estrutural Torre'!$E$4:$E$4199,"SPC FMT",'Estrutural Torre'!$I$4:$I$4199,"<>") -> 0 | L19: 0 | M19: 0 | S19: 0 | T19: 0 | U19: 0 | V19: 0 | W19: 0 | AR19: 0 | AS19: 0 | AT19: 0 | AU19: 0 | AV19: 0 | AW19: =COUNTIF(FMT!E$3:E$5000,"SPC") -> 218 | AX19: =COUNTIFS(FMT!E$3:E$5000,"SPC",FMT!H$3:H$5000,"<>") -> 218 | AY19: =COUNTIFS(FMT!E$3:E$5000,"SPC",FMT!I$3:I$5000,"<>") -> 218 | AZ19: =IF(AW19=0,"",(AX19/AW19)) -> 1 | BA19: =IF(AW19=0,"",(AY19/AW19)) -> 1 | BB19: =D19+I19+N19+S19+X19+AC19+AH19+AM19+AR19+AW19 -> 218 | BC19: =E19+J19+O19+T19+Y19+AD19+AI19+AN19+AS19+AX19 -> 218 | BD19: =F19+K19+P19+U19+Z19+AE19+AJ19+AO19+AT19+AY19 -> 218 | BE19: =BC19/BB19 -> 1 | BF19: =BD19/BB19 -> 1
A20: 11 | B20: CORE SPC | C20: WALTER BARRANCO | D20: 0 | E20: 0 | F20: 0 | G20: 0 | H20: 0 | I20: 0 | J20: 0 | K20: =COUNTIFS('Estrutural Torre'!$E$4:$E$4199,"CORE SPC",'Estrutural Torre'!$I$4:$I$4199,"<>") -> 0 | L20: 0 | M20: 0 | S20: 0 | T20: 0 | U20: 0 | V20: 0 | W20: 0 | AR20: =COUNTIF(CCCs!L$3:L$100,"WALTER BARRANCO") -> 4 | AS20: =COUNTIFS(CCCs!L$3:L$100,"WALTER BARRANCO",CCCs!J$3:J$100,"<>") -> 4 | AT20: =COUNTIFS(CCCs!L$3:L$100,"WALTER BARRANCO",CCCs!K$3:K$100,"<>") -> 4 | AU20: =IF(AR20=0,"",(AS20/AR20)) -> 1 | AV20: =IF(AR20=0,"",(AT20/AR20)) -> 1 | AW20: 0 | AX20: 0 | AY20: 0 | AZ20: 0 | BA20: 0 | BB20: =D20+I20+N20+S20+X20+AC20+AH20+AM20+AR20+AW20 -> 4 | BC20: =E20+J20+O20+T20+Y20+AD20+AI20+AN20+AS20+AX20 -> 4 | BD20: =F20+K20+P20+U20+Z20+AE20+AJ20+AO20+AT20+AY20 -> 4 | BE20: =BC20/BB20 -> 1 | BF20: =BD20/BB20 -> 1
N27: mensal | X27: anual | AH27: anual | BB27: =SUM(BB4:BB26) -> 1671 | BC27: =SUM(BC4:BC26) -> 1669 | BD27: =SUM(BD4:BD26) -> 1566 | BE27: =BC27/BB27 -> 0.99880311 | BF27: =BD27/BB27 -> 0.93716338
D28: PR | F28: PROGRAMADAS
D29: EX | F29: EXECUTADAS
D30: REL | F30: RELATÓRIOS ENTREGUES
D31: APROV | F31: OK EM PORCENTAGEM
D32: REAL | F32: EXECUTADOS + RELATÓRIOS ENTREGUES
D33: PROG2 | F33: TOTAL DE PROGRAMADAS
D34: EXEC2 | F34: TOTAL DE EXECURADAS
D35: RELATO2 | F35: TOTAL DE RELATÓRIOS ENTREGUES
D36: APROV2 | F36: TOTAL OK EM PORCENTAGEM
D37: REAL2 | F37: TOTAL EXECUTADOS + RELATÓRIOS ENTREGUES

Sheet Planilha2
H3: ÁREA | I3: PROGRAMADO | J3: EXECUTADO | K3: RELATÓRIO | L3: SEM ACESSO | M3: DESATIVADO | N3: INEXISTENTE | O3: NÃO ATIVO | P3: ACESSO | Q3: EXECUTADO REAL
H4: SJC | I4: 92 | J4: 92 | P4: =SUM(L4:O4) -> 0 | Q4: =J4-P4 -> 92
H5: STS | I5: 66 | J5: 66 | P5: =SUM(L5:O5) -> 0 | Q5: =J5-P5 -> 66
H6: BRU | I6: 48 | J6: 48 | P6: =SUM(L6:O6) -> 0 | Q6: =J6-P6 -> 48
H7: SOC | I7: 39 | J7: 39 | L7: 3 | P7: =SUM(L7:O7) -> 3 | Q7: =J7-P7 -> 36
H8: RPO | I8: 57 | J8: 57 | M8: 2 | P8: =SUM(L8:O8) -> 2 | Q8: =J8-P8 -> 55
H9: SRR | I9: 43 | J9: 43 | M9: 1 | P9: =SUM(L9:O9) -> 1 | Q9: =J9-P9 -> 42
H10: PPE | I10: 33 | J10: 33 | P10: =SUM(L10:O10) -> 0 | Q10: =J10-P10 -> 33
H11: PAA | I11: 57 | J11: 57 | L11: 11 | M11: 1 | P11: =SUM(L11:O11) -> 12 | Q11: =J11-P11 -> 45
H12: CAS | I12: 55 | J12: 55 | L12: 7 | N12: 1 | P12: =SUM(L12:O12) -> 8 | Q12: =J12-P12 -> 47
H13: Q2 | I13: 109 | J13: 109 | L13: 7 | M13: 1 | P13: =SUM(L13:O13) -> 8 | Q13: =J13-P13 -> 101
H14: Q1 | I14: 127 | J14: 127 | L14: 10 | P14: =SUM(L14:O14) -> 10 | Q14: =J14-P14 -> 117
H15: Q3 | I15: 103 | J15: 103 | L15: 4 | M15: 1 | O15: 1 | P15: =SUM(L15:O15) -> 6 | Q15: =J15-P15 -> 97
H16: Q4 | I16: 99 | J16: 99 | P16: =SUM(L16:O16) -> 0 | Q16: =J16-P16 -> 99
H17: JAI | I17: 23 | J17: 23 | L17: 1 | M17: 1 | P17: =SUM(L17:O17) -> 2 | Q17: =J17-P17 -> 21
H18: CORE SPC | I18: 4 | J18: 4 | P18: =SUM(L18:O18) -> 0 | Q18: =J18-P18 -> 4
H19: TOTAL | I19: =SUM(I4:I18) -> 955 | J19: =SUM(J4:J18) -> 955 | K19: =SUM(K4:K18) -> 0 | L19: =SUM(L4:L18) -> 43 | M19: =SUM(M4:M18) -> 7 | N19: =SUM(N4:N18) -> 1 | O19: =SUM(O4:O18) -> 1 | P19: =SUM(P4:P18) -> 52 | Q19: =SUM(Q4:Q18) -> 903

Sheet MacroChart
A5: PROGRAMADA | B5: 43070
B6: PREVENTIVAS INFRA - Novembro-2017
B7: Values
A8: Rótulos de Linha | B8: Count of PROGRAMADA | C8: Count of EXECUTADA | D8: Contagem de RELATÓRIO
A9: WALLACE OLIVEIRA LEITE LIMA | B9: 97 | C9: 97 | D9: 97
A10: ANDERSON GOMES TOSTA / ENRIQUE JOSE MICHELS | B10: 31 | C10: 31 | D10: 31
A11: GESIVANDO DE OLIVEIRA SILVA / VINICIUS MESEL DE MELO | B11: 33 | C11: 33 | D11: 33
A12: EDGAR RODRIGUES/GENIVALDO OLIVIERA | B12: 32 | C12: 32 | D12: 32
A13: ANDERSON GOMES/ENRIQUE JOSE | B13: 1 | C13: 1 | D13: 1
A14: RODOLFO ALVES VITORINO | B14: 89 | C14: 89 | D14: 89
A15: FELIPE FERREIRA PENNA / HAMILTON CARLOS DE OLIVEIRA | B15: 30 | C15: 30 | D15: 30
A16: SIDNEI LIMA DE BARROS / MILTON JOSE DE LANNES SILVA | B16: 31 | C16: 31 | D16: 31
A17: ALESSANDRO DE MOURA NOBRE / CLEBER EDUARDO SANCHES | B17: 28 | C17: 28 | D17: 28
A18: SERGIO NILTON DA CUNHA | B18: 88 | C18: 88 | D18: 88
A19: EMANUEL MACHADO DOS PASSOS SILVA | B19: 22 | C19: 22 | D19: 22
A20: ANDRE LUIS FRANCA | B20: 22 | C20: 22 | D20: 22
... A40: EVANDRO BOSCOLO | B40: 2 | C40: 2 | D40: 2
A41: MARIO ROGERIO DOS SANTOS | B41: 1
A42: CRISTIAN FERREIRA ROSA | B42: 25 | C42: 25 | D42: 14
A43: ANTONIO ARAGAO | B43: 25 | C43: 25 | D43: 14
A44: REINALDO SOARES CAMARGO | B44: 41 | C44: 41 | D44: 41
A45: LUIZ ADRIANO SILVA | B45: 3 | C45: 3 | D45: 3
A46: FERNANDO JOSE DE MEDEIROS GOMES | B46: 7 | C46: 7 | D46: 7
A47: CRISTIANO CESAR DE OLIVEIRA | B47: 3 | C47: 3 | D47: 3
A48: ADRIANO DOS SANTOS FERNANDES | B48: 5 | C48: 5 | D48: 5
A49: THIAGO FABRICIO DA SILVA BASTOS | B49: 6 | C49: 6 | D49: 6
A50: HELIO VINICIUS CORTEZ BONASORTE | B50: 7 | C50: 7 | D50: 7
A51: EDERSON DA SILVA VITORIO | B51: 4 | C51: 4 | D51: 4
A52: ELEANDRO DA SILVA DAMIANI | B52: 5 | C52: 5 | D52: 5
A53: REINALDO SOARES CAMARGO | B53: 1 | C53: 1 | D53: 1
... A102: Total Geral | B102: 810 | C102: 808 | D102: 795
A138: PROGRAMADA | B138: 43070
B140: PREVENTIVAS - ESTRUTURAL TORRE
A141: Rótulos de Linha | B141: Count of PROGRAMADA | C141: Count of EXECUTADA | D141: Contagem de RELATÓRIO
A142: WALLACE OLIVEIRA LEITE LIMA | B142: 31 | C142: 31 | D142: 31
A143: RODOLFO ALVES VITORINO | B143: 20 | C143: 20 | D143: 20
A144: SERGIO NILTON DA CUNHA | B144: 30 | C144: 30 | D144: 30
A145: RODOLFO LEITE LIMA | B145: 37 | C145: 37 | D145: 37
A146: MARIO ROGERIO DOS SANTOS | B146: 26 | C146: 26
A147: CRISTIAN FERREIRA ROSA | B147: 9 | C147: 9 | D147: 9
...

Sheet Chart

Sheet BTS-TX
A1: PREVENTIVAS NOVEMBRO 2017
A2: TX
A3: SIGLA | B3: CIDADE | C3: MICRO-AREAS | D3: DDD | E3: ÁREA | F3: TÉCNICOS | G3: PROGRAMADA | H3: EXECUTADA | I3: RELATÓRIO | J3: SUPERVISOR
A4: SLSPMN01 | B4: SAO PAULO | C4: Q4 | D4: 11 | F4: SAULO DE SOUZA LEITE | G4: 43040 | H4: 43055 | I4: 43068 | J4: RODOLFO ALVES VITORINO
A5: SLSPPN20 | B5: SAO PAULO | C5: Q4 | D5: 11 | F5: ROBSON DE CASSIO TOLEDO | G5: 43040 | H5: 43060 | I5: 43075 | J5: RODOLFO LEITE LIMA
A6: SLSPVP03 | B6: SAO PAULO | C6: Q4 | D6: 11 | F6: JOSIMAR PEREIRA DA CUNHA | G6: 43040 | H6: 43063 | I6: 43075 | J6: SERGIO NILTON DA CUNHA
A7: ARNH01 | B7: ARACARIGUAMA | C7: Q2 | D7: 11 | F7: SAULO DE SOUZA LEITE | G7: 43040 | H7: 43074 | I7: 43075 | J7: RODOLFO ALVES VITORINO
A8: SNSH01 | B8: ARACARIGUAMA | C8: Q2 | D8: 11 | F8: SAULO DE SOUZA LEITE | G8: 43040 | H8: 43066 | I8: 43075 | J8: RODOLFO ALVES VITORINO
A9: AJJS01 | B9: ARUJA | C9: Q1 | D9: 11 | F9: CLOVIS ALMEIDA DE SOUZA / FELIPE EDENILSON DA CUNHA | G9: 43040 | H9: 43061 | I9: 43075 | J9: SERGIO NILTON DA CUNHA
A10: BACT01 | B10: BARUERI | C10: Q2 | D10: 11 | F10: SAULO DE SOUZA LEITE | G10: 43040 | H10: 43056 | I10: 43075 | J10: RODOLFO ALVES VITORINO
A11: BAJM01 | B11: BARUERI | C11: Q2 | D11: 11 | F11: SAULO DE SOUZA LEITE | G11: 43040 | H11: 43052 | I11: 43075 | J11: RODOLFO ALVES VITORINO
A12: BAPC01 | B12: BARUERI | C12: Q2 | D12: 11 | F12: SAULO DE SOUZA LEITE | G12: 43040 | H12: 43052 | I12: 43075 | J12: RODOLFO ALVES VITORINO
A13: BATM01 | B13: BARUERI | C13: Q2 | D13: 11 | F13: SAULO DE SOUZA LEITE | G13: 43040 | H13: 43055 | I13: 43075 | J13: RODOLFO ALVES VITORINO
A14: CMSB01 | B14: CAJAMAR | C14: Q2 | D14: 11 | F14: SAULO DE SOUZA LEITE | G14: 43040 | H14: 43066 | I14: 43075 | J14: RODOLFO ALVES VITORINO
A15: CMSI01 | B15: CAJAMAR | C15: Q2 | D15: 11 | F15: SAULO DE SOUZA LEITE | G15: 43040 | H15: 43066 | I15: 43068 | J15: RODOLFO ALVES VITORINO
... A23: GRBS01 | B23: GUARULHOS | C23: Q1 | D23: 11 | F23: CLOVIS ALMEIDA DE SOUZA / FELIPE EDENILSON DA CUNHA | G23: 43040 | H23: 43061 | I23: 43075 | J23: SERGIO NILTON DA CUNHA
A24: GRCM04 | B24: GUARULHOS | C24: Q1 | D24: 11 | F24: CLOVIS ALMEIDA DE SOUZA / FELIPE EDENILSON DA CUNHA | G24: 43040 | H24: S/ ACESSO | I24: S/ ACESSO | J24: SERGIO NILTON DA CUNHA
A25: GRCM05 | B25: GUARULHOS | C25: Q1 | D25: 11 | F25: CLOVIS ALMEIDA DE SOUZA / FELIPE EDENILSON DA CUNHA | G25: 43040 | H25: S/ ACESSO | I25: S/ ACESSO | J25: SERGIO NILTON DA CUNHA
A26: GRCS01 | B26: GUARULHOS | C26: Q1 | D26: 11 | F26: CLOVIS ALMEIDA DE SOUZA / FELIPE EDENILSON DA CUNHA | G26: 43040 | H26: 43066 | I26: 43075 | J26: SERGIO NILTON DA CUNHA
A27: GRJA01 | B27: GUARULHOS | C27: Q1 | D27: 11 | F27: CLOVIS ALMEIDA DE SOUZA / FELIPE EDENILSON DA CUNHA | G27: 43040 | H27: 43066 | I27: 43075 | J27: SERGIO NILTON DA CUNHA
A28: GRPB02 | B28: GUARULHOS | C28: Q1 | D28: 11 | F28: CLOVIS ALMEIDA DE SOUZA / FELIPE EDENILSON DA CUNHA | G28: 43040 | H28: 43066 | I28: 43075 | J28: SERGIO NILTON DA CUNHA
A29: GRSM01 | B29: GUARULHOS | C29: Q1 | D29: 11 | F29: CLOVIS ALMEIDA DE SOUZA / FELIPE EDENILSON DA CUNHA | G29: 43040 | H29: 43049 | I29: 43061 | J29: SERGIO NILTON DA CUNHA
A30: GRVA01 | B30: GUARULHOS | C30: Q1 | D30: 11 | F30: CLOVIS ALMEIDA DE SOUZA / FELIPE EDENILSON DA CUNHA | G30: 43040 | H30: 43049 | I30: 43061 | J30: SERGIO NILTON DA CUNHA
A31: IQBV01 | B31: ITAQUAQUECETUBA | C31: Q1 | D31: 11 | F31: CLOVIS ALMEIDA DE SOUZA / FELIPE EDENILSON DA CUNHA | G31: 43040 | H31: 43061 | I31: 43075 | J31: SERGIO NILTON DA CUNHA
A32: IQJI01 | B32: ITAQUAQUECETUBA | C32: Q1 | D32: 11 | F32: CLOVIS ALMEIDA DE SOUZA / FELIPE EDENILSON DA CUNHA | G32: 43040 | H32: 43052 | I32: 43075 | J32: SERGIO NILTON DA CUNHA
A33: MCSB01 | B33: MOGI DAS CRUZES | C33: Q1 | D33: 11 | F33: CLOVIS ALMEIDA DE SOUZA / FELIPE EDENILSON DA CUNHA | G33: 43040 | H33: 43055 | I33: 43075 | J33: SERGIO NILTON DA CUNHA
A34: IPNI01 | B34: ITAPEVI | C34: Q2 | D34: 11 | F34: SAULO DE SOUZA LEITE | G34: 43040 | H34: 43060 | I34: 43075 | J34: RODOLFO ALVES VITORINO
A35: ITHB01 | B35: ITU | C35: Q2 | D35: 11 | F35: SAULO DE SOUZA LEITE | G35: 43040 | H35: 43070 | I35: 43075 | J35: RODOLFO ALVES VITORINO
A36: ITPR01 | B36: ITU | C36: Q2 | D36: 11 | F36: SAULO DE SOUZA LEITE | G36: 43040 | H36: 43070 | I36: 43075 | J36: RODOLFO ALVES VITORINO
A37: ITPR02 | B37: ITU | C37: Q2 | D37: 11 | F37: SAULO DE SOUZA LEITE | G37: 43040 | H37: 43070 | I37: 43075 | J37: RODOLFO ALVES VITORINO
... A69: SLSPSR01 | B69: SAO PAULO | C69: Q1 | D69: 11 | F69: CLOVIS ALMEIDA DE SOUZA / FELIPE EDENILSON DA CUNHA | G69: 43040 | H69: 43069 | I69: 43075 | J69: SERGIO NILTON DA CUNHA
A70: SLSPIB23 | B70: SAO PAULO | C70: Q3 | D70: 11 | F70: ROBSON DE CASSIO TOLEDO | G70: 43040 | H70: S/ ACESSO | I70: S/ ACESSO | J70: RODOLFO LEITE LIMA
A71: SLSPIB25 | B71: SAO PAULO | C71: Q3 | D71: 11 | F71: ROBSON DE CASSIO TOLEDO | G71: 43040 | H71: 43063 | I71: 43068 | J71: RODOLFO LEITE LIMA
A72: SLSPPZ02 | B72: SAO PAULO | C72: Q2 | D72: 11 | F72: SAULO DE SOUZA LEITE | G72: 43040 | H72: 43067 | I72: 43068 | J72: RODOLFO ALVES VITORINO
A73: SLSPRP06 | B73: SAO PAULO | C73: Q2 | D73: 11 | F73: SAULO DE SOUZA LEITE | G73: 43040 | H73: 43049 | I73: 43068 | J73: RODOLFO ALVES VITORINO
A74: SLSPRT03 | B74: SAO PAULO | C74: Q2 | D74: 11 | F74: SAULO DE SOUZA LEITE | G74: 43040 | H74: 43048 | I74: 43068 | J74: RODOLFO ALVES VITORINO
A75: SLSPSU05 | B75: SAO PAULO | C75: Q1 | D75: 11 | F75: CLOVIS ALMEIDA DE SOUZA / FELIPE EDENILSON DA CUNHA | G75: 43040 | H75: 43073 | I75: 43075 | J75: SERGIO NILTON DA CUNHA
A76: SLSPJN04 | B76: SAO PAULO | C76: Q3 | D76: 11 | F76: ROBSON DE CASSIO TOLEDO | G76: 43040 | H76: 43063 | I76: 43068 | J76: RODOLFO LEITE LIMA
A77: SLSPTT12 | B77: SAO PAULO | C77: Q1 | D77: 11 | F77: CLOVIS ALMEIDA DE SOUZA / FELIPE EDENILSON DA CUNHA | G77: 43040 | H77: 43073 | I77: 43075 | J77: SERGIO NILTON DA CUNHA
A78: SLSPTC04 | B78: SAO PAULO | C78: Q2 | D78: 11 | F78: SAULO DE SOUZA LEITE | G78: 43040 | H78: 43047 | I78: 43068 | J78: RODOLFO ALVES VITORINO
...

Sheet Infra
A1: PREVENTIVAS DE NOVEMBRO 2017
A2: INFRA
A3: SIGLA | B3: CIDADE | C3: MICRO-AREAS | D3: DDD | E3: ÁREA | F3: TÉCNICOS | G3: PROGRAMADA | H3: EXECUTADA | I3: RELATÓRIO | J3: SUPERVISOR
A4: CGTT01 | B4: CARAGUATATUBA | C4: SJC | D4: 12 | E4: SJC | F4: LEANDRO DE PAIVA PEREIRA | G4: 43070 | H4: 43097 | I4: 43103 | J4: DENILSON ANDRADE DE MELO
A5: IBBB01 | B5: ILHABELA | C5: SJC | D5: 12 | E5: SJC | F5: LEANDRO DE PAIVA PEREIRA | G5: 43070 | H5: 43087 | I5: 43103 | J5: DENILSON ANDRADE DE MELO
A6: IBCT01 | B6: ILHABELA | C6: SJC | D6: 12 | E6: SJC | F6: LEANDRO DE PAIVA PEREIRA | G6: 43070 | H6: 43087 | I6: 43103 | J6: DENILSON ANDRADE DE MELO
A7: IBPS01 | B7: ILHABELA | C7: SJC | D7: 12 | E7: SJC | F7: LEANDRO DE PAIVA PEREIRA | G7: 43070 | H7: 43087 | I7: 43103 | J7: DENILSON ANDRADE DE MELO
A8: ARNH01 | B8: ARACARIGUAMA | C8: Q2 | D8: 11 | F8: FELIPE FERREIRA PENNA / HAMILTON CARLOS DE OLIVEIRA | G8: 43040 | H8: 43068 | I8: 43068 | J8: RODOLFO ALVES VITORINO
A9: AJJS01 | B9: ARUJA | C9: Q1 | D9: 11 | F9: EMANUEL MACHADO DOS PASSOS SILVA | G9: 43040 | H9: 43068 | I9: 43075 | J9: SERGIO NILTON DA CUNHA
A10: BATM01 | B10: BARUERI | C10: Q2 | D10: 11 | F10: SIDNEI LIMA DE BARROS / MILTON JOSE DE LANNES SILVA | G10: 43040 | H10: 43068 | I10: 43068 | J10: RODOLFO ALVES VITORINO
A11: FMNB01 | B11: FRANCISCO MORATO | C11: Q2 | D11: 11 | F11: FELIPE FERREIRA PENNA | G11: 43040 | H11: 43048 | I11: 43068 | J11: RODOLFO ALVES VITORINO
A12: FRBC01 | B12: FRANCO DA ROCHA | C12: Q2 | D12: 11 | F12: FELIPE FERREIRA PENNA / HAMILTON CARLOS DE OLIVEIRA | G12: 43040 | H12: 43053 | I12: 43068 | J12: RODOLFO ALVES VITORINO
A13: FRCT01 | B13: FRANCO DA ROCHA | C13: Q2 | D13: 11 | F13: FELIPE FERREIRA PENNA / HAMILTON CARLOS DE OLIVEIRA | G13: 43040 | H13: 43052 | I13: 43068 | J13: RODOLFO ALVES VITORINO
A14: GRCM04 | B14: GUARULHOS | C14: Q1 | D14: 11 | F14: ANDRE LUIS FRANCA | G14: 43040 | H14: S/ ACESSO | I14: S/ ACESSO | J14: SERGIO NILTON DA CUNHA
A15: GRCM05 | B15: GUARULHOS | C15: Q1 | D15: 11 | F15: REINALDO DOS SANTOS MORALES / VIVALDO DIAS DOS SANTOS | G15: 43040 | H15: S/ ACESSO | I15: S/ ACESSO | J15: SERGIO NILTON DA CUNHA
A16: GRSM01 | B16: GUARULHOS | C16: Q1 | D16: 11 | F16: ANDRE LUIS FRANCA | G16: 43040 | H16: 43055 | I16: 43055 | J16: SERGIO NILTON DA CUNHA
A17: GRVA01 | B17: GUARULHOS | C17: Q1 | D17: 11 | F17: REINALDO DOS SANTOS MORALES / VIVALDO DIAS DOS SANTOS | G17: 43040 | H17: 43055 | I17: 43055 | J17: SERGIO NILTON DA CUNHA
A18: IQBV01 | B18: ITAQUAQUECETUBA | C18: Q1 | D18: 11 | F18: ANDRE LUIS FRANCA | G18: 43040 | H18: 43049 | I18: 43055 | J18: SERGIO NILTON DA CUNHA
A19: IQJI01 | B19: ITAQUAQUECETUBA | C19: Q1 | D19: 11 | F19: REINALDO DOS SANTOS MORALES / VIVALDO DIAS DOS SANTOS | G19: 43040 | H19: 43049 | I19: 43061 | J19: SERGIO NILTON DA CUNHA
A20: MCSB01 | B20: MOGI DAS CRUZES | C20: Q1 | D20: 11 | F20: REINALDO DOS SANTOS MORALES / VIVALDO DIAS DOS SANTOS | G20: 43040 | H20: 43056 | I20: 43061 | J20: SERGIO NILTON DA CUNHA
A21: ITHB01 | B21: ITU | C21: Q2 | D21: 11 | F21: ALESSANDRO DE MOURA NOBRE / CLEBER EDUARDO SANCHES | G21: 43040 | H21: 43073 | I21: 43075 | J21: RODOLFO ALVES VITORINO
A22: ITPR01 | B22: ITU | C22: Q2 | D22: 11 | F22: ALESSANDRO DE MOURA NOBRE / CLEBER EDUARDO SANCHES | G22: 43040 | H22: 43073 | I22: 43075 | J22: RODOLFO ALVES VITORINO
A23: ITPR02 | B23: ITU | C23: Q2 | D23: 11 | F23: ALESSANDRO DE MOURA NOBRE | G23: 43040 | H23: 43046 | I23: 43075 | J23: RODOLFO ALVES VITORINO
A24: ITSJ01 | B24: ITU | C24: Q2 | D24: 11 | F24: ALESSANDRO DE MOURA NOBRE / CLEBER EDUARDO SANCHES | G24: 43040 | H24: 43073 | I24: 43075 | J24: RODOLFO ALVES VITORINO
A25: MRAC01 | B25: MAIRIPORA | C25: Q2 | D25: 11 | F25: FELIPE FERREIRA PENNA / HAMILTON CARLOS DE OLIVEIRA | G25: 43040 | H25: 43056 | I25: 43075 | J25: RODOLFO ALVES VITORINO
A26: MASM03 | B26: MAUA | C26: Q4 | D26: 11 | F26: ANDERSON GOMES TOSTA / ENRIQUE JOSE MICHELS | G26: 43040 | H26: 43045 | I26: 43061 | J26: WALLACE OLIVEIRA LEITE LIMA
A27: MASV01 | B27: MAUA | C27: Q4 | D27: 11 | F27: ANDERSON GOMES TOSTA / ENRIQUE JOSE MICHELS | G27: 43040 | H27: 43049 | I27: 43068 | J27: WALLACE OLIVEIRA LEITE LIMA
... A32: JQRDRP | B32: JUQUIA | C32: STS | D32: 13 | F32: ANDERSON CARLOS ALVES DE OLIVEIRA / JEAN VITOR TAVARES PRADO | G32: 43040 | H32: 43063 | I32: 43068 | J32: MARIO ROGERIO DOS SANTOS
A33: BPCP01 | B33: BRAGANCA PAULISTA | C33: JAI | D33: JAI | F33: ANTONIO ARAGAO | G33: 43040 | H33: 43074 | I33: 43075 | J33: CRISTIAN FERREIRA ROSA
A34: JN120S | B34: JUNDIAI | C34: JAI | D34: JAI | F34: ANTONIO ARAGAO | G34: 43040 | H34: 43052 | I34: 43068 | J34: CRISTIAN FERREIRA ROSA
A35: BAAH01 | B35: BARUERI | C35: Q2 | D35: 11 | F35: SIDNEI LIMA DE BARROS / MILTON JOSE DE LANNES SILVA | G35: 43040 | H35: 43056 | I35: 43068 | J35: RODOLFO ALVES VITORINO
A36: SLSNMP01 | B36: SANTANA DE PARNAIBA | C36: Q2 | D36: 11 | F36: FELIPE FERREIRA PENNA / HAMILTON CARLOS DE OLIVEIRA | G36: 43040 | H36: 43068 | I36: 43068 | J36: RODOLFO ALVES VITORINO
A37: BAAH08 | B37: BARUERI | C37: Q2 | D37: 11 | F37: SIDNEI LIMA DE BARROS / MILTON JOSE DE LANNES SILVA | G37: 43040 | H37: 43070 | I37: 43075 | J37: RODOLFO ALVES VITORINO
A38: FRSR01 | B38: CAJAMAR | C38: Q2 | D38: 11 | F38: FELIPE FERREIRA PENNA / HAMILTON CARLOS DE OLIVEIRA | G38: 43040 | H38: 43073 | I38: 43075 | J38: RODOLFO ALVES VITORINO
A39: DDVM02 | B39: DIADEMA | C39: Q4 | D39: 11 | F39: GENIVALDO OLIVEIRA DE ALMEIDA / EDGAR RODRIGUES | G39: 43040 | H39: 43052 | I39: 43055 | J39: WALLACE OLIVEIRA LEITE LIMA
A40: MABE02 | B40: MAUA | C40: Q4 | D40: 11 | F40: ANDERSON GOMES TOSTA / ENRIQUE JOSE MICHELS | G40: 43040 | H40: 43053 | I40: 43075 | J40: WALLACE OLIVEIRA LEITE LIMA
A41: MABE04 | B41: MAUA | C41: Q4 | D41: 11 | F41: ANDERSON GOMES TOSTA / ENRIQUE JOSE MICHELS | G41: 43040 | H41: 43066 | I41: 43068 | J41: WALLACE OLIVEIRA LEITE LIMA
A42: GRAM01 | B42: GUARULHOS | C42: Q1 | D42: 11 | F42: EMANUEL MACHADO DOS PASSOS SILVA | G42: 43040 | H42: S/ ACESSO | I42: S/ ACESSO | J42: SERGIO NILTON DA CUNHA
A43: GRCM03 | B43: GUARULHOS | C43: Q1 | D43: 11 | F43: REINALDO DOS SANTOS MORALES / VIVALDO DIAS DOS SANTOS | G43: 43040 | H43: S/ ACESSO | I43: S/ ACESSO | J43: SERGIO NILTON DA CUNHA
A44: ISJJ02 | B44: ITAPECERICA DA SERRA | C44: Q3 | D44: 11 | F44: SAMUEL FREDERICO CESAR SANTOS / RENATO HIDEKI MENEGHINI | G44: 43040 | H44: 43070 | I44: 43075 | J44: RODOLFO LEITE LIMA
...

Sheet FMT
A1: PREVENTIVAS DE NOVEMBRO 2017
A2: FMT
A3: SIGLA | B3: CIDADE | C3: MICRO-AREAS | D3: DDD | E3: ÁREA | F3: TÉCNICOS | G3: PROGRAMADA | H3: EXECUTADA | I3: RELATÓRIO | J3: SUPERVISOR
A4: SPCM01 | B4: SAO PAULO | C4: FTTS | D4: 11 | E4: SPC | F4: ADSTON BARBOSA DOS SANTOS | G4: 43070 | H4: 43103 | I4: 43103 | J4: ADSTON BARBOSA DOS SANTOS
A5: SPIB13 | B5: SAO PAULO | C5: FTTS | D5: 11 | E5: SPC | F5: ADSTON BARBOSA DOS SANTOS | G5: 43070 | H5: S/ ACESSO | I5: S/ ACESSO | J5: ADSTON BARBOSA DOS SANTOS
A6: SPGR10 | B6: SAO PAULO | C6: FTTS | D6: 11 | E6: SPC | F6: ADSTON BARBOSA DOS SANTOS | G6: 43070 | H6: 43103 | I6: 43103 | J6: ADSTON BARBOSA DOS SANTOS
A7: GJSA01 | B7: GUARUJA | C7: FTTS | D7: 11 | E7: SPC | F7: ADSTON BARBOSA DOS SANTOS | G7: 43070 | H7: 43104 | I7: 43104 | J7: ADSTON BARBOSA DOS SANTOS
A8: SACM01 | B8: SANTO ANDRE | C8: FTTS | D8: 11 | E8: SPC | F8: ADSTON BARBOSA DOS SANTOS | G8: 43070 | H8: 43098 | I8: 43098 | J8: ADSTON BARBOSA DOS SANTOS
A9: SAUT01 | B9: SANTO ANDRE | C9: FTTS | D9: 11 | E9: SPC | F9: ADSTON BARBOSA DOS SANTOS | G9: 43070 | H9: 43103 | I9: 43103 | J9: ADSTON BARBOSA DOS SANTOS
A10: SBPQ01 | B10: SAO BERNARDO DO CAMPO | C10: FTTS | D10: 11 | E10: SPC | F10: ADSTON BARBOSA DOS SANTOS | G10: 43070 | H10: 43103 | I10: 43103 | J10: ADSTON BARBOSA DOS SANTOS
A11: SPCA02 | B11: SAO PAULO | C11: FTTS | D11: 11 | E11: SPC | F11: ADSTON BARBOSA DOS SANTOS | G11: 43070 | H11: 43098 | I11: 43098 | J11: ADSTON BARBOSA DOS SANTOS
A12: SPEM04 | B12: SAO PAULO | C12: FTTS | D12: 11 | E12: SPC | F12: ADSTON BARBOSA DOS SANTOS | G12: 43070 | H12: 43098 | I12: 43098 | J12: ADSTON BARBOSA DOS SANTOS
A13: SPJS05 | B13: SAO PAULO | C13: FTTS | D13: 11 | E13: SPC | F13: ADSTON BARBOSA DOS SANTOS | G13: 43070 | H13: 43089 | I13: 43092 | J13: ADSTON BARBOSA DOS SANTOS
A14: SPSL03 | B14: SAO PAULO | C14: FTTS | D14: 11 | E14: SPC | F14: ADSTON BARBOSA DOS SANTOS | G14: 43070 | H14: 43104 | I14: 43104 | J14: ADSTON BARBOSA DOS SANTOS
A15: EBDJ01 | B15: EMBU | C15: FTTS | D15: 11 | E15: SPC | F15: ADSTON BARBOSA DOS SANTOS | G15: 43070 | H15: 43098 | I15: 43098 | J15: ADSTON BARBOSA DOS SANTOS
A16: EBJF01 | B16: EMBU | C16: FTTS | D16: 11 | E16: SPC | F16: ADSTON BARBOSA DOS SANTOS | G16: 43070 | H16: 43098 | I16: 43098 | J16: ADSTON BARBOSA DOS SANTOS
A17: SAJL01 | B17: SANTO ANDRE | C17: FTTS | D17: 11 | E17: SPC | F17: ADSTON BARBOSA DOS SANTOS | G17: 43070 | H17: 43098 | I17: 43098 | J17: ADSTON BARBOSA DOS SANTOS
... A79: SPMR12 | B79: SAO PAULO | C79: FTTS | D79: 11 | E79: SPC | F79: ADSTON BARBOSA DOS SANTOS | G79: 43070 | H79: 43089 | I79: 43092 | J79: ADSTON BARBOSA DOS SANTOS
A80: SPMR14 | B80: SAO PAULO | C80: FTTS | D80: 11 | E80: SPC | F80: ADSTON BARBOSA DOS SANTOS | G80: 43070 | H80: S/ ACESSO | I80: S/ ACESSO | J80: ADSTON BARBOSA DOS SANTOS
A81: SPMR16 | B81: SAO PAULO | C81: FTTS | D81: 11 | E81: SPC | F81: ADSTON BARBOSA DOS SANTOS | G81: 43070 | H81: 43104 | I81: 43104 | J81: ADSTON BARBOSA DOS SANTOS
A82: SPMR17 | B82: SAO PAULO | C82: FTTS | D82: 11 | E82: SPC | F82: ADSTON BARBOSA DOS SANTOS | G82: 43070 | H82: 43089 | I82: 43092 | J82: ADSTON BARBOSA DOS SANTOS
A83: SPMR21 | B83: SAO PAULO | C83: FTTS | D83: 11 | E83: SPC | F83: ADSTON BARBOSA DOS SANTOS | G83: 43070 | H83: 43089 | I83: 43092 | J83: ADSTON BARBOSA DOS SANTOS
A84: SPMR22 | B84: SAO PAULO | C84: FTTS | D84: 11 | E84: SPC | F84: ADSTON BARBOSA DOS SANTOS | G84: 43070 | H84: 43104 | I84: 43104 | J84: ADSTON BARBOSA DOS SANTOS
A85: SPMR23 | B85: SAO PAULO | C85: FTTS | D85: 11 | E85: SPC | F85: ADSTON BARBOSA DOS SANTOS | G85: 43070 | H85: 43104 | I85: 43104 | J85: ADSTON BARBOSA DOS SANTOS
A86: SPMR24 | B86: SAO PAULO | C86: FTTS | D86: 11 | E86: SPC | F86: ADSTON BARBOSA DOS SANTOS | G86: 43070 | H86: 43105 | I86: 43105 | J86: ADSTON BARBOSA DOS SANTOS
A87: SPMR25 | B87: SAO PAULO | C87: FTTS | D87: 11 | E87: SPC | F87: ADSTON BARBOSA DOS SANTOS | G87: 43070 | H87: S/ ACESSO | I87: S/ ACESSO | J87: ADSTON BARBOSA DOS SANTOS
A88: SPMR27 | B88: SAO PAULO | C88: FTTS | D88: 11 | E88: SPC | F88: ADSTON BARBOSA DOS SANTOS | G88: 43070 | H88: 43089 | I88: 43092 | J88: ADSTON BARBOSA DOS SANTOS
A89: SPPC01 | B89: SAO PAULO | C89: FTTS | D89: 11 | E89: SPC | F89: ADSTON BARBOSA DOS SANTOS | G89: 43070 | H89: 43098 | I89: 43098 | J89: ADSTON BARBOSA DOS SANTOS
A90: SPPC02 | B90: SAO PAULO | C90: FTTS | D90: 11 | E90: SPC | F90: ADSTON BARBOSA DOS SANTOS | G90: 43070 | H90: 43098 | I90: 43098 | J90: ADSTON BARBOSA DOS SANTOS
A91: SPPC03 | B91: SAO PAULO | C91: FTTS | D91: 11 | E91: SPC | F91: ADSTON BARBOSA DOS SANTOS | G91: 43070 | H91: 43098 | I91: 43098 | J91: ADSTON BARBOSA DOS SANTOS
A92: SPPD01 | B92: SAO PAULO | C92: FTTS | D92: 11 | E92: SPC | F92: ADSTON BARBOSA DOS SANTOS | G92: 43070 | H92: 43097 | I92: 43097 | J92: ADSTON BARBOSA DOS SANTOS
A93: SPPD02 | B93: SAO PAULO | C93: FTTS | D93: 11 | E93: SPC | F93: ADSTON BARBOSA DOS SANTOS | G93: 43070 | H93: 43103 | I93: 43103 | J93: ADSTON BARBOSA DOS SANTOS
A94: SPPD03 | B94: SAO PAULO | C94: FTTS | D94: 11 | E94: SPC | F94: ADSTON BARBOSA DOS SANTOS | G94: 43070 | H94: 43097 | I94: 43097 | J94: ADSTON BARBOSA DOS SANTOS
A95: SPPD05 | B95: SAO PAULO | C95: FTTS | D95: 11 | E95: SPC | F95: ADSTON BARBOSA DOS SANTOS | G95: 43070 | H95: 43098 | I95: 43098 | J95: ADSTON BARBOSA DOS SANTOS
A96: SPPD06 | B96: SAO PAULO | C96: FTTS | D96: 11 | E96: SPC | F96: ADSTON BARBOSA DOS SANTOS | G96: 43070 | H96: 43098 | I96: 43098 | J96: ADSTON BARBOSA DOS SANTOS
A97: SPPD08 | B97: SAO PAULO | C97: FTTS | D97: 11 | E97: SPC | F97: ADSTON BARBOSA DOS SANTOS | G97: 43070 | H97: 43098 | I97: 43098 | J97: ADSTON BARBOSA DOS SANTOS
A98: SPPH01 | B98: SAO PAULO | C98: FTTS | D98: 11 | E98: SPC | F98: ADSTON BARBOSA DOS SANTOS | G98: 43070 | H98: 43089 | I98: 43092 | J98: ADSTON BARBOSA DOS SANTOS
A99: SPPH02 | B99: SAO PAULO | C99: FTTS | D99: 11 | E99: SPC | F99: ADSTON BARBOSA DOS SANTOS | G99: 43070 | H99: 43097 | I99: 43097 | J99: ADSTON BARBOSA DOS SANTOS
... A104: SPPH12 | B104: SAO PAULO | C104: FTTS | D104: 11 | E104: SPC | F104: ADSTON BARBOSA DOS SANTOS | G104: 43070 | H104: 43097 | I104: 43097 | J104: ADSTON BARBOSA DOS SANTOS
A105: SPPH13 | B105: SAO PAULO | C105: FTTS | D105: 11 | E105: SPC | F105: ADSTON BARBOSA DOS SANTOS | G105: 43070 | H105: S/ ACESSO | I105: S/ ACESSO | J105: ADSTON BARBOSA DOS SANTOS
...

Sheet Estrutural Torre
A1: PREVENTIVAS DE NOVEMBRO 2017
A2: ESTRUTURAL TORRE
A3: SIGLA | B3: CIDADE | C3: MICRO-AREAS | D3: DDD | E3: ÁREA | F3: TÉCNICOS | G3: PROGRAMADA | H3: EXECUTADA | I3: RELATÓRIO | J3: SUPERVISOR
A4: SLSPMN01 | C4: Q4 | G4: 43405 | J4: WALLACE OLIVEIRA LEITE LIMA
A5: SLSPPN20 | C5: Q4 | G5: 43405 | J5: WALLACE OLIVEIRA LEITE LIMA
A6: SLSPVP03 | C6: Q4 | G6: 43405 | J6: WALLACE OLIVEIRA LEITE LIMA
A7: ARNH01 | C7: Q2 | G7: 43405 | J7: RODOLFO ALVES VITORINO
A8: SNSH01 | C8: Q2 | G8: 43405 | J8: RODOLFO ALVES VITORINO
A9: AJJS01 | C9: Q1 | G9: 43405 | J9: SERGIO NILTON DA CUNHA
A10: BACT01 | C10: Q2 | G10: 43405 | J10: RODOLFO ALVES VITORINO
A11: BAJM01 | C11: Q2 | G11: 43405 | J11: RODOLFO ALVES VITORINO
A12: BAPC01 | C12: Q2 | G12: 43405 | J12: RODOLFO ALVES VITORINO
A13: BATM01 | C13: Q2 | G13: 43405 | J13: RODOLFO ALVES VITORINO
A14: CMSB01 | C14: Q2 | G14: 43405 | J14: RODOLFO ALVES VITORINO
A15: CMSI01 | C15: Q2 | G15: 43405 | J15: RODOLFO ALVES VITORINO
... A146: JNCT01 | C146: JAI | G146: 43405 | J146: CRISTIAN FERREIRA ROSA
A147: BAAH01 | C147: Q2 | E147: Q2 | F147: =J147 -> RODOLFO ALVES VITORINO | G147: 43070 | H147: 43095 | I147: 43103 | J147: RODOLFO ALVES VITORINO
A148: SLSNMP01 | C148: Q2 | E148: SPC EV | F148: WERIQUE BRAGA DA SILVA | G148: 43070 | H148: 43103 | I148: 43103 | J148: LEONARDO RUGGIERO
A149: BAAH08 | C149: Q2 | E149: SPC EV | F149: WERIQUE BRAGA DA SILVA | G149: 43070 | H149: 43103 | I149: 43103 | J149: LEONARDO RUGGIERO
A150: FRSR01 | C150: Q2 | E150: Q2 | F150: =J150 -> RODOLFO ALVES VITORINO | G150: 43070 | H150: 43089 | I150: 43103 | J150: RODOLFO ALVES VITORINO
A151: SLCOGJ03 | C151: Q2 | E151: SPC EV | F151: WERIQUE BRAGA DA SILVA | G151: 43070 | H151: 43054 | I151: 43096 | J151: LEONARDO RUGGIERO
A152: DDCT02 | C152: Q4 | E152: SPC EV | F152: WERIQUE BRAGA DA SILVA | G152: 43070 | H152: 43054 | I152: 43096 | J152: LEONARDO RUGGIERO
A153: DDJN01 | C153: Q4 | E153: Q4 | F153: =J153 -> WALLACE OLIVEIRA LEITE LIMA | G153: 43070 | H153: 43104 | I153: 43105 | J153: WALLACE OLIVEIRA LEITE LIMA
A154: MABE02 | C154: Q4 | E154: Q4 | F154: =J154 -> WALLACE OLIVEIRA LEITE LIMA | G154: 43070 | H154: 43054 | I154: 43105 | J154: WALLACE OLIVEIRA LEITE LIMA
A155: MABE04 | C155: Q4 | E155: Q4 | F155: =J155 -> WALLACE OLIVEIRA LEITE LIMA | G155: 43070 | H155: 43054 | I155: 43105 | J155: WALLACE OLIVEIRA LEITE LIMA
A156: MCBB01 | C156: Q1 | E156: Q1 | F156: =J156 -> SERGIO NILTON DA CUNHA | G156: 43070 | H156: 43095 | I156: 43105 | J156: SERGIO NILTON DA CUNHA
A157: MCSP01 | C157: Q1 | E157: Q1 | F157: =J157 -> SERGIO NILTON DA CUNHA | G157: 43070 | H157: 43095 | I157: 43105 | J157: SERGIO NILTON DA CUNHA
A158: MCVB01 | C158: Q1 | E158: Q1 | F158: =J158 -> SERGIO NILTON DA CUNHA | G158: 43070 | H158: 43095 | I158: 43105 | J158: SERGIO NILTON DA CUNHA
A159: GRAM01 | C159: Q1 | E159: SPC EV | F159: WERIQUE BRAGA DA SILVA | G159: 43070 | H159: 43103 | I159: 43103 | J159: LEONARDO RUGGIERO
A160: GRCM03 | C160: Q1 | E160: SPC EV | F160: WERIQUE BRAGA DA SILVA | G160: 43070 | H160: 43054 | I160: 43103 | J160: LEONARDO RUGGIERO
A161: PAVR01 | C161: Q1 | E161: Q1 | F161: =J161 -> SERGIO NILTON DA CUNHA | G161: 43070 | H161: 43105 | I161: 43105 | J161: SERGIO NILTON DA CUNHA
A162: SICH02 | C162: Q1 | E162: Q1 | F162: =J162 -> SERGIO NILTON DA CUNHA | G162: 43070 | H162: 43095 | I162: 43105 | J162: SERGIO NILTON DA CUNHA
A163: SLSPAR05 | C163: Q1 | E163: Q1 | F163: =J163 -> SERGIO NILTON DA CUNHA | G163: 43070 | H163: 43095 | I163: 43105 | J163: SERGIO NILTON DA CUNHA
A164: ISJJ02 | C164: Q3 | E164: Q3 | F164: =J164 -> RODOLFO LEITE LIMA | G164: 43070 | H164: 43096 | I164: 43103 | J164: RODOLFO LEITE LIMA
A165: SLSPEM04 | C165: Q1 | E165: Q1 | F165: =J165 -> SERGIO NILTON DA CUNHA | G165: 43070 | H165: 43095 | I165: 43105 | J165: SERGIO NILTON DA CUNHA
A166: SLSPIA03 | C166: Q1 | E166: SPC EV | F166: WERIQUE BRAGA DA SILVA | G166: 43070 | H166: 43054 | I166: 43105 | J166: LEONARDO RUGGIERO
A167: SACT02 | C167: Q4 | E167: Q4 | F167: =J167 -> WALLACE OLIVEIRA LEITE LIMA | G167: 43070 | H167: 43104 | I167: 43105 | J167: WALLACE OLIVEIRA LEITE LIMA
A168: SBST02 | C168: Q4 | E168: Q4 | F168: =J168 -> WALLACE OLIVEIRA LEITE LIMA | G168: 43070 | H168: 43095 | I168: 43105 | J168: WALLACE OLIVEIRA LEITE LIMA
A169: SBVV01 | C169: Q4 | E169: Q4 | F169: =J169 -> WALLACE OLIVEIRA LEITE LIMA | G169: 43070 | H169: 43104 | I169: 43105 | J169: WALLACE OLIVEIRA LEITE LIMA
A170: SLSPCO06 | C170: Q4 | E170: Q4 | F170: =J170 -> WALLACE OLIVEIRA LEITE LIMA | G170: 43070 | H170: 43054 | I170: 43105 | J170: WALLACE OLIVEIRA LEITE LIMA
...

Sheet CCCs
A1: PREVENTIVAS CCC´S DEZEMBRO DE 2017
A2: SITE | B2: SITE | C2: DETENTORA | D2: PS | E2: DDD | F2: ÁREA | G2: TECNICO | H2: ID | I2: PROGRAMADA | J2: EXECUTADA | K2: RELATÓRIO | L2: SUPERVISOR | M2: CSP | N2: GMG | O2: EVENTO
A3: Giovanni Gronchi | B3: Giovanni Gronchi | C3: TIM | E3: 11 | F3: GG | G3: CHICO GG | I3: 43070 | J3: 43097 | K3: 43102 | L3: WALTER BARRANCO
A4: Vila Mariana | B4: Vila Mariana | C4: TIM | E4: 11 | F4: VM | G4: WALTER BARRANCO | I4: 43070 | J4: 43097 | K4: 43102 | L4: WALTER BARRANCO
A5: Campinas | B5: Campinas | C5: TIM | E5: 19 | F5: CAS | G5: ALEX MARTINS | I5: 43070 | J5: 43097 | K5: 43102 | L5: LEOPOLDO DE SOUSA E SILVA
A6: Campinas - Intelig | B6: Campinas - Intelig | C6: TIM | E6: 19 | F6: CAS | G6: ALEX MARTINS | I6: 43070 | J6: 43097 | K6: 43102 | L6: LEOPOLDO DE SOUSA E SILVA
A7: São José dos Campos | B7: São José dos Campos | C7: TIM | E7: 12 | F7: SJC | G7: GUSTAVO | I7: 43070 | J7: 43097 | K7: 43102 | L7: DENILSON ANDRADE DE MELO
A8: Caraguatatuba | B8: Caraguatatuba | C8: TIM | E8: 12 | F8: SJC | G8: GUSTAVO | I8: 43070 | J8: 43097 | K8: 43102 | L8: DENILSON ANDRADE DE MELO
A9: Ribeirão Preto | B9: Ribeirão Preto | C9: TIM | E9: 16 | F9: RPO | G9: EDWALDO ESTRELLA GRAMIGNA | I9: 43070 | J9: 43097 | K9: 43102 | L9: MARCOS MIGUELETTI DE CARVALHO
A10: Santos | B10: Santos | C10: TIM | E10: 13 | F10: STS | G10: WALTER BARRANCO | I10: 43070 | J10: 43097 | K10: 43102 | L10: WALTER BARRANCO
A11: Bauru | B11: Bauru | C11: TIM | E11: 14 | F11: BRU | G11: MAIK DOUGLAS FELIX | I11: 43070 | J11: 43097 | K11: 43102 | L11: REINALDO SOARES CAMARGO
A12: Sorocaba | B12: Sorocaba | C12: TIM | E12: 15 | F12: SOC | G12: MARCIO ROBERTO DE JESUS | I12: 43070 | J12: 43097 | K12: 43102 | L12: PAULO ROBERTO DOS SANTOS
A13: São José do Rio Preto | B13: São José do Rio Preto | C13: TIM | E13: 17 | F13: SRR | G13: ELIEL ALEXANDRE | I13: 43070 | J13: 43097 | K13: 43102 | L13: MILTON SONEHARA
A14: Presidente Prudente | B14: Presidente Prudente | C14: TIM | E14: 18 | F14: PPE | G14: VALTEMIR APARECIDO | I14: 43070 | J14: 43097 | K14: 43102 | L14: ROGERIO CARNELOS MARSICANO
A15: Lapa | B15: Lapa | C15: TIM | E15: 11 | F15: LP | G15: WALTER BARRANCO | I15: 43070 | J15: 43097 | K15: 43102 | L15: WALTER BARRANCO

Sheet EVT
A1: PREVENTIVAS DEZEMBRO 2014 | S1: TEMPO DECORRIDO
A2: TORRE
A3: SIGLA | B3: SITE | C3: DETENTORA | D3: P. S | E3: DDD | F3: ÁREA | G3: TIPO | H3: C.M | I3: UF | J3: DATA DE ATIVAÇÃO | K3: SUPERVISOR | L3: TÉCNICOS | M3: ID | N3: EXECUTADA | O3: PROGRAMADA | P3: RELATÓRIO | Q3: Nº C. A. | R3: OBSERVAÇÃO | S3: CSP | T3: FINAL | U3: TOTAL | V3: preventiva

Sheet Ramal de AC
A1: PREVENTIVAS DEZEMBRO 2014 | S1: TEMPO DECORRIDO
A2: RAMAL AC
A3: SIGLA | B3: SITE | C3: DETENTORA | D3: P. S | E3: DDD | F3: ÁREA | G3: TIPO | H3: C.M | I3: UF | J3: DATA DE ATIVAÇÃO | K3: SUPERVISOR | L3: TÉCNICOS | M3: ID | N3: EXECUTADA | O3: PROGRAMADA | P3: RELATÓRIO | Q3: Nº C. A. | R3: OBSERVAÇÃO | S3: CSP | T3: FINAL | U3: TOTAL | V3: preventiva

Sheet REPETIDOR
A1: PREVENTIVAS DE REPETIDOR DEZEMBRO 2014 | M1: TEMPO DECORRIDO
A2: REPETIDOR | B2: ENDEREÇO | C2: C.M | D2: U.F | E2: TÉCNICO | F2: ID | G2: SUPERVISOR | H2: EXECUTADA | I2: PROGRAMADA | J2: RELATÓRIO | K2: Nº C. A. | L2: OBSERVAÇÃO | M2: INICIAL | N2: FINAL | O2: TOTAL

Sheet SITE_ULTIMAMILHA
A1: PREVENTIVAS ULTIMA MILHA DEZEMBRO 2014
A2: SITE | B2: CM | C2: UF | D2: SUPERVISOR | E2: TÉCNICO | F2: ID | G2: EXECUTADA | H2: PROGRAMADA | I2: RELATÓRIO
